<?xml version="1.0" ?>
<robot name="vehicle_blue">
  <!-- Chassi -->
  <link name="chassis">
    <visual>
      <geometry>
        <box size="2.0 1.0 0.5"/>
      </geometry>
      <material name="blue_material">
        <color rgba="0.0 0.0 1.0 1"/>
      </material>
    </visual>
    <collision>
      <geometry>
        <box size="2.0 1.0 0.5"/>
      </geometry>
    </collision>
    <inertial>
      <mass>1.14395</mass>
      <inertia>
        <ixx>0.095329</ixx>
        <iyy>0.381317</iyy>
        <izz>0.476646</izz>
      </inertia>
    </inertial>
  </link>

  <!-- Roda Esquerda -->
  <link name="left_wheel">
    <visual>
      <geometry>
        <cylinder radius="0.4" length="0.2"/>
      </geometry>
      <material name="red_material">
        <color rgba="1.0 0.0 0.0 1"/>
      </material>
    </visual>
    <collision>
      <geometry>
        <cylinder radius="0.4" length="0.2"/>
      </geometry>
    </collision>
    <inertial>
      <mass>1.0</mass>
      <inertia>
        <ixx>0.043333</ixx>
        <iyy>0.043333</iyy>
        <izz>0.08</izz>
      </inertia>
    </inertial>
  </link>

  <!-- Roda Direita -->
  <link name="right_wheel">
    <visual>
      <geometry>
        <cylinder radius="0.4" length="0.2"/>
      </geometry>
      <material name="red_material">
        <color rgba="1.0 0.0 0.0 1"/>
      </material>
    </visual>
    <collision>
      <geometry>
        <cylinder radius="0.4" length="0.2"/>
      </geometry>
    </collision>
    <inertial>
      <mass>1.0</mass>
      <inertia>
        <ixx>0.043333</ixx>
        <iyy>0.043333</iyy>
        <izz>0.08</izz>
      </inertia>
    </inertial>
  </link>

  <!-- Roda Caster -->
  <link name="caster">
    <visual>
      <geometry>
        <sphere radius="0.2"/>
      </geometry>
      <material name="green_material">
        <color rgba="0.0 1.0 0.0 1"/>
      </material>
    </visual>
    <collision>
      <geometry>
        <sphere radius="0.2"/>
      </geometry>
    </collision>
    <inertial>
      <mass>1.0</mass>
      <inertia>
        <ixx>0.016</ixx>
        <iyy>0.016</iyy>
        <izz>0.016</izz>
      </inertia>
    </inertial>
  </link>

  <!-- Juntas -->
  <joint name="left_wheel_joint" type="revolute">
    <parent link="chassis"/>
    <child link="left_wheel"/>
    <origin xyz="-0.5 0.6 0" rpy="0 -1.5707 0"/>
    <axis xyz="0 1 0"/>
    <limit lower="-1.79769e+308" upper="1.79769e+308"/>
  </joint>

  <joint name="right_wheel_joint" type="revolute">
    <parent link="chassis"/>
    <child link="right_wheel"/>
    <origin xyz="-0.5 -0.6 0" rpy="0 -1.5707 0"/>
    <axis xyz="0 1 0"/>
    <limit lower="-1.79769e+308" upper="1.79769e+308"/>
  </joint>

  <joint name="caster_joint" type="ball">
    <parent link="chassis"/>
    <child link="caster"/>
    <origin xyz="0.8 0 -0.2"/>
  </joint>
</robot>
